Workbook

Sheet Ret
A1: Refresh | B1: Last Update : 2025-06-19 08:32:11
A2: 0
A3: Time Series (Company)
A4: Frequency | B4: M | C4: Ascending | D4: 0
A5: Period(From) | B5: 20200504 | C5: Korean | D5: 0
A6: Period(To) | B6: 20250531 | D6: 0
A8: Code | B8: Name | C8: Item Code | D8: Unit | E8: Base Date | G8: 43980 | H8: 44012 | I8: 44043 | J8: 44074 | K8: 44103 | L8: 44134 | M8: 44165 | N8: 44195 | O8: 44225 | P8: 44253 | Q8: 44286 | R8: 44316 | S8: 44347 | T8: 44377 | U8: 44407 | V8: 44439 | W8: 44469 | X8: 44498 | Y8: 44530 | Z8: 44560 | AA8: 44589 | AB8: 44620 | AC8: 44651 | AD8: 44680 | AE8: 44712 | AF8: 44742 | AG8: 44771 | AH8: 44804 | AI8: 44834 | AJ8: 44865 | AK8: 44895 | AL8: 44924 | AM8: 44957 | AN8: 44985 | AO8: 45016 | AP8: 45044 | AQ8: 45077 | AR8: 45107 | AS8: 45138 | AT8: 45169 | AU8: 45196 | AV8: 45230 | AW8: 45260 | AX8: 45288 | AY8: 45322 | AZ8: 45351 | BA8: 45380 | BB8: 45412 | BC8: 45443 | BD8: 45471 | BE8: 45504 | BF8: 45534 | BG8: 45565 | BH8: 45596 | BI8: 45625 | BJ8: 45656 | BK8: 45688 | BL8: 45716 | BM8: 45747 | BN8: 45777 | BO8: 45807
A9: IKS270 | B9: 코스피 200 TR | C9: S302600 | D9: % | F9: 월간수익률 | G9: 3.93 | H9: 4.7 | I9: 6.86 | J9: 2.6 | K9: 0.92 | L9: -2.54 | M9: 14.73 | N9: 13.7 | O9: 3.93 | P9: 1.32 | Q9: 2.08 | R9: 1.75 | S9: 1.32 | T9: 2.71 | U9: -3.34 | V9: -0.94 | W9: -4.26 | X9: -3.19 | Y9: -3.9 | Z9: 6.68 | AA9: -9.18 | AB9: 0.99 | AC9: 1.64 | AD9: -2.84 | AE9: -0.14 | AF9: -13.09 | AG9: 5.28 | AH9: -0.1 | AI9: -12.66 | AJ9: 6.53 | AK9: 7.15 | AL9: -7.75 | AM9: 8.99 | AN9: -0.78 | AO9: 2.44 | AP9: 1.38 | AQ9: 3.87 | AR9: -0.02 | AS9: 2.27 | AT9: -3.12 | AU9: -2.16 | AV9: -6.42 | AW9: 10.76 | AX9: 6.56 | AY9: -6.08 | AZ9: 6.05 | BA9: 5.89 | BB9: -2.52 | BC9: -1.88 | BD9: 7.48 | BE9: -0.88 | BF9: -4.94 | BG9: -4.39 | BH9: -1.55 | BI9: -4.09 | BJ9: -1.95 | BK9: 4.9 | BL9: 0.78 | BM9: 0.11 | BN9: 1.98 | BO9: 6.3
A10: A005930 | B10: 삼성전자 | C10: S310600 | D10: % | F10: 월간수익률(현금배당포함) | G10: 1.4 | H10: 4.84 | I10: 9.66 | J10: -6.74 | K10: 8.43 | L10: -2.75 | M10: 17.84 | N10: 24.43 | O10: 1.23 | P10: 0.61 | Q10: -0.9 | R10: 0.12 | S10: -1.23 | T10: 0.69 | U10: -2.73 | V10: -2.29 | W10: -2.92 | X10: -5.8 | Y10: 2.15 | Z10: 10.32 | AA10: -6.39 | AB10: -1.64 | AC10: -2.97 | AD10: -3.16 | AE10: 0 | AF10: -14.9 | AG10: 7.72 | AH10: -2.77 | AI10: -10.45 | AJ10: 11.86 | AK10: 4.71 | AL10: -10.53 | AM10: 10.31 | AN10: -0.66 | AO10: 6.21 | AP10: 2.34 | AQ10: 9.01 | AR10: 1.62 | AS10: -3.33 | AT10: -4.16 | AU10: 2.78 | AV10: -2.19 | AW10: 8.82 | AX10: 8.33 | AY10: -7.39 | AZ10: 0.96 | BA10: 12.76 | BB10: -5.95 | BC10: -5.16 | BD10: 11.37 | BE10: 2.94 | BF10: -11.44 | BG10: -16.76 | BH10: -3.74 | BI10: -8.45 | BJ10: -1.18 | BK10: -1.5 | BL10: 4.01 | BM10: 6.7 | BN10: -3.98 | BO10: 1.26
A11: A000660 | B11: SK하이닉스 | C11: S310600 | D11: % | F11: 월간수익률(현금배당포함) | G11: -2.63 | H11: 4.42 | I11: -2.7 | J11: -9.3 | K11: 11.85 | L11: -4.88 | M11: 22.03 | N11: 22.76 | O11: 3.37 | P11: 15.51 | Q11: -6.36 | R11: -3.4 | S11: -0.78 | T11: 0.39 | U11: -11.77 | V11: -5.33 | W11: -3.29 | X11: 0 | Y11: 10.68 | Z11: 16.3 | AA11: -8.02 | AB11: 2.49 | AC11: -4.22 | AD11: -4.66 | AE11: -4 | AF11: -15.47 | AG11: 7.58 | AH11: -2.76 | AI11: -12.39 | AJ11: -0.48 | AK11: 2.78 | AL11: -11.42 | AM11: 18 | AN11: 1.02 | AO11: -0.56 | AP11: 1.01 | AQ11: 21.34 | AR11: 6.35 | AS11: 7.12 | AT11: -1.3 | AU11: -5.58 | AV11: 1.39 | AW11: 15.13 | AX11: 5.9 | AY11: -4.81 | AZ11: 15.96 | BA11: 17.35 | BB11: -4.81 | BC11: 8.61 | BD11: 25.16 | BE11: -17.72 | BF11: -10.74 | BG11: 0.68 | BH11: 6.7 | BI11: -14.17 | BJ11: 8.75 | BK11: 14.55 | BL11: -3.89 | BM11: 0.26 | BN11: -6.92 | BO11: 15.41
A12: A373220 | B12: LG에너지솔루션 | C12: S310600 | D12: % | F12: 월간수익률(현금배당포함) | AA12: -10.89 | AB12: -8.45 | AC12: 7.28 | AD12: -5.66 | AE12: 6.47 | AF12: -16.44 | AG12: 13.75 | AH12: 9.6 | AI12: -7.78 | AJ12: 23.8 | AK12: 11.17 | AL12: -25.81 | AM12: 19.63 | AN12: 0.38 | AO12: 11.66 | AP12: -0.51 | AQ12: 3.1 | AR12: -7.68 | AS12: 1.27 | AT12: -2.86 | AU12: -12.41 | AV12: -19.1 | AW12: 17.9 | AX12: -5.94 | AY12: -10.88 | AZ12: 5.38 | BA12: -1.62 | BB12: -1.52 | BC12: -14.91 | BD12: -1.36 | BE12: -0.77 | BF12: 19.75 | BG12: 6.83 | BH12: -1.69 | BI12: -6.38 | BJ12: -8.78 | BK12: 1.15 | BL12: 0 | BM12: -4.97 | BN12: -2.99 | BO12: -11.87
A13: A207940 | B13: 삼성바이오로직스 | C13: S310600 | D13: % | F13: 월간수익률(현금배당포함) | G13: 7.06 | H13: 24.6 | I13: -5.42 | J13: 6.14 | K13: -11.31 | L13: -1.16 | M13: 15.25 | N13: 5.09 | O13: -4 | P13: -5.42 | Q13: -0.27 | R13: 7.49 | S13: 5.1 | T13: -0.47 | U13: 5.83 | V13: 8.43 | W13: -9.43 | X13: -0.34 | Y13: 2.07 | Z13: 1.57 | AA13: -18.16 | AB13: 6.66 | AC13: 6.16 | AD13: 1.33 | AE13: 1.07 | AF13: -6.73 | AG13: 9.49 | AH13: -3.47 | AI13: -3.35 | AJ13: 8.67 | AK13: 1.14 | AL13: -7.44 | AM13: -3.41 | AN13: -2.52 | AO13: 1.94 | AP13: -0.89 | AQ13: 0.38 | AR13: -5.1 | AS13: 2.96 | AT13: -3.79 | AU13: -7.6 | AV13: 4.11 | AW13: 2.26 | AX13: 4.83 | AY13: 10.53 | AZ13: -7.86 | BA13: 7.36 | BB13: -6.02 | BC13: -6.53 | BD13: -0.41 | BE13: 29.02 | BF13: 4.48 | BG13: -0.31 | BH13: 2.56 | BI13: -2.7 | BJ13: -2.67 | BK13: 13.91 | BL13: 3.24 | BM13: -9.14 | BN13: 3.75 | BO13: -1.9
A14: A005380 | B14: 현대차 | C14: S310600 | D14: % | F14: 월간수익률(현금배당포함) | G14: 4.7 | H14: -0.31 | I14: 29.48 | J14: 39.52 | K14: 1.13 | L14: -7.84 | M14: 10.33 | N14: 7.45 | O14: 19.27 | P14: 3.49 | Q14: -8.02 | R14: -2.75 | S14: 10.85 | T14: 2.34 | U14: -8.98 | V14: -2.52 | W14: -5.88 | X14: 4 | Y14: -6.01 | Z14: 8.92 | AA14: -9.33 | AB14: -7.65 | AC14: 3.14 | AD14: 3.05 | AE14: 1.88 | AF14: -4.21 | AG14: 8.59 | AH14: 0 | AI14: -9.95 | AJ14: -6.8 | AK14: 2.73 | AL14: -7.17 | AM14: 10.59 | AN14: 5.57 | AO14: 4.65 | AP14: 7.05 | AQ14: 1.26 | AR14: 4.01 | AS14: -5.09 | AT14: -3.52 | AU14: 1.85 | AV14: -11.2 | AW14: 8.6 | AX14: 10.42 | AY14: -4.37 | AZ14: 33.08 | BA14: -6.2 | BB14: 7.72 | BC14: 0.8 | BD14: 17.38 | BE14: -15.59 | BF14: 2.61 | BG14: -3.75 | BH14: -11.89 | BI14: 1.63 | BJ14: -2.98 | BK14: -2.83 | BL14: -3.51 | BM14: 2.18 | BN14: -3.35 | BO14: -1.51
A15: A068270 | B15: 셀트리온 | C15: S310600 | D15: % | F15: 월간수익률(현금배당포함) | G15: 1.42 | H15: 43.32 | I15: -3.11 | J15: 0.17 | K15: -13.3 | L15: -6.41 | M15: 41.08 | N15: 7.52 | O15: -9.75 | P15: -8.18 | Q15: 9.07 | R15: -18.03 | S15: 3.19 | T15: -2.19 | U15: -5.59 | V15: 15.58 | W15: -11.43 | X15: -22.74 | Y15: 3.24 | Z15: -2.19 | AA15: -23.74 | AB15: 5.63 | AC15: 7.52 | AD15: 2.62 | AE15: -8.81 | AF15: 11.21 | AG15: 6.44 | AH15: -0.26 | AI15: -7.39 | AJ15: 9.4 | AK15: -8.33 | AL15: -5.12 | AM15: 0.68 | AN15: -10.15 | AO15: 3.17 | AP15: 7.21 | AQ15: 6.66 | AR15: -10.74 | AS15: -4.12 | AT15: -1.84 | AU15: -3.27 | AV15: 7.4 | AW15: 8.96 | AX15: 24.02 | AY15: -10.82 | AZ15: 0 | BA15: 6.4 | BB15: -1.15 | BC15: -6.77 | BD15: -1.08 | BE15: 17.33 | BF15: -0.73 | BG15: -3.74 | BH15: -6.6 | BI15: 2.46 | BJ15: 5.4 | BK15: -4.16 | BL15: 2.39 | BM15: -8.15 | BN15: -4.56 | BO15: -0.19
A16: A000270 | B16: 기아 | C16: S310600 | D16: % | F16: 월간수익률(현금배당포함) | G16: 15.51 | H16: -6.42 | I16: 26.05 | J16: 5.07 | K16: 10.48 | L16: 7.68 | M16: 14.45 | N16: 9.69 | O16: 32.21 | P16: -3.76 | Q16: 4.41 | R16: -7.12 | S16: 11.17 | T16: 4.67 | U16: -6.7 | V16: 1.79 | W16: -4.58 | X16: 4.8 | Y16: -8.58 | Z16: 9.45 | AA16: -0.24 | AB16: -10 | AC16: 0.27 | AD16: 13.24 | AE16: 2.27 | AF16: -9.8 | AG16: 5.04 | AH16: -0.49 | AI16: -11.02 | AJ16: -7.79 | AK16: 3.47 | AL16: -8.59 | AM16: 12.65 | AN16: 12.72 | AO16: 7.57 | AP16: 4.32 | AQ16: 1.66 | AR16: 3.03 | AS16: -6.55 | AT16: -3.02 | AU16: 1.5 | AV16: -5.53 | AW16: 11.7 | AX16: 16.41 | AY16: 2.9 | AZ16: 20.99 | BA16: -7.32 | BB16: 7.08 | BC16: -0.26 | BD16: 9.85 | BE16: -13.3 | BF16: -5.35 | BG16: -5.84 | BH16: -8.01 | BI16: 1.09 | BJ16: 8.39 | BK16: 1.29 | BL16: -8.63 | BM16: 5.71 | BN16: -2.06 | BO16: -1.11
A17: A105560 | B17: KB금융 | C17: S310600 | D17: % | F17: 월간수익률(현금배당포함) | G17: -2.16 | H17: -0.15 | I17: 3.83 | J17: 4.54 | K17: 1.9 | L17: 6.79 | M17: 13.09 | N17: -0.4 | O17: -7.14 | P17: 8.68 | Q17: 28.31 | R17: -2.67 | S17: 7.49 | T17: -3.83 | U17: -8.07 | V17: 3.12 | W17: 4.54 | X17: 2.35 | Y17: -6.71 | Z17: 8.28 | AA17: 8.18 | AB17: 0.34 | AC17: 3.53 | AD17: -4.57 | AE17: 3.25 | AF17: -19.45 | AG17: 0.62 | AH17: 2.06 | AI17: -10.63 | AJ17: 9.95 | AK17: 9.26 | AL17: -4.91 | AM17: 15.26 | AN17: -8.23 | AO17: -6.11 | AP17: 3.88 | AQ17: -3.03 | AR17: 0.56 | AS17: 6.81 | AT17: 6.08 | AU17: 3.15 | AV17: -6.87 | AW17: 1.75 | AX17: 3.24 | AY17: 4.62 | AZ17: 14.95 | BA17: 10.67 | BB17: 8.78 | BC17: 5.03 | BD17: -0.14 | BE17: 11.97 | BF17: -2.28 | BG17: -4.93 | BH17: 11.62 | BI17: 6.53 | BJ17: -13.83 | BK17: 10.61 | BL17: -13.76 | BM17: 0.89 | BN17: 14.18 | BO17: 16.78
A18: A005490 | B18: POSCO홀딩스 | C18: S310600 | D18: % | F18: 월간수익률(현금배당포함) | G18: -1.9 | H18: -3.59 | I18: 11.21 | J18: -4.65 | K18: 7.05 | L18: 6.12 | M18: 12.5 | N18: 18.18 | O18: -9.74 | P18: 14.66 | Q18: 14.73 | R18: 13.75 | S18: -2.47 | T18: -0.84 | U18: 5.31 | V18: -8.05 | W18: -0.59 | X18: -10.3 | Y18: -11.83 | Z18: 7.06 | AA18: -3.46 | AB18: 7.55 | AC18: 4.22 | AD18: -1.37 | AE18: 0 | AF18: -18.88 | AG18: 4.99 | AH18: 5.37 | AI18: -16.5 | AJ18: 18.01 | AK18: 20.28 | AL18: -7.05 | AM18: 8.68 | AN18: 5.82 | AO18: 16.57 | AP18: 2.44 | AQ18: -4.51 | AR18: 8.47 | AS18: 65.46 | AT18: -9.81 | AU18: -7.17 | AV18: -23.08 | AW18: 17.37 | AX18: 3.42 | AY18: -14.72 | AZ18: 1.87 | BA18: -1.62 | BB18: -4.03 | BC18: -8.89 | BD18: -0.94 | BE18: -3.17 | BF18: -3.27 | BG18: 13.97 | BH18: -12.86 | BI18: -15.8 | BJ18: -10.27 | BK18: 2.76 | BL18: 5.54 | BM18: 2.2 | BN18: -6.46 | BO18: -3.02
A19: A035420 | B19: NAVER | C19: S310600 | D19: % | F19: 월간수익률(현금배당포함) | G19: 14.43 | H19: 18.14 | I19: 12.73 | J19: 7.14 | K19: -8.06 | L19: -2.19 | M19: -4.31 | N19: 5.55 | O19: 17.26 | P19: 9.33 | Q19: 0.53 | R19: -4.64 | S19: 0.83 | T19: 15.17 | U19: 3.83 | V19: 1.27 | W19: -11.62 | X19: 4.9 | Y19: -6.39 | Z19: -0.52 | AA19: -18.1 | AB19: 2.58 | AC19: 7.07 | AD19: -15.86 | AE19: 0.52 | AF19: -16.67 | AG19: 7.92 | AH19: -7.34 | AI19: -19 | AJ19: -12.4 | AK19: 10.32 | AL19: -5.08 | AM19: 14.08 | AN19: 2.96 | AO19: -3.12 | AP19: -4.8 | AQ19: 3.74 | AR19: -8.16 | AS19: 24.18 | AT19: -5.51 | AU19: -6.06 | AV19: -7 | AW19: 10.99 | AX19: 8.07 | AY19: -10.49 | AZ19: -2.74 | BA19: -3.9 | BB19: -1.6 | BC19: -7.7 | BD19: -1.94 | BE19: 4.25 | BF19: -2.82 | BG19: 0.18 | BH19: 0.35 | BI19: 21.47 | BJ19: -3.68 | BK19: 8.85 | BL19: -3.9 | BM19: -7.73 | BN19: 4.97 | BO19: -6.48
A20: A055550 | B20: 신한지주 | C20: S310600 | D20: % | F20: 월간수익률(현금배당포함) | G20: -1.31 | H20: -4.64 | I20: 4.69 | J20: -1.5 | K20: -6.91 | L20: 9.96 | M20: 6.09 | N20: 4.2 | O20: -4.37 | P20: 7.5 | Q20: 13.66 | R20: 6.81 | S20: 6.12 | T20: -3.66 | U20: -3.57 | V20: -0.77 | W20: 4.67 | X20: -5.32 | Y20: -9.41 | Z20: 10.2 | AA20: 3.67 | AB20: 2.36 | AC20: 7.3 | AD20: 1.57 | AE20: 2.13 | AF20: -13.03 | AG20: -3.64 | AH20: 2.52 | AI20: -7.4 | AJ20: 8.36 | AK20: 4.96 | AL20: -5.39 | AM20: 18.04 | AN20: -6.5 | AO20: -7.65 | AP20: -1.13 | AQ20: 0.28 | AR20: -1.49 | AS20: 3.09 | AT20: 1.43 | AU20: 1.62 | AV20: -2.39 | AW20: 6.19 | AX20: 8.81 | AY20: 1.74 | AZ20: 7.92 | BA20: 6.83 | BB20: 1.41 | BC20: 1.07 | BD20: 3.29 | BE20: 24.19 | BF20: -6.19 | BG20: -0.12 | BH20: -7.57 | BI20: 3.31 | BJ20: -10.09 | BK20: 7.24 | BL20: -9.25 | BM20: 2.62 | BN20: 10.46 | BO20: 13.03
A21: A012330 | B21: 현대모비스 | C21: S310600 | D21: % | F21: 월간수익률(현금배당포함) | G21: 15.12 | H21: -3.03 | I21: 7.03 | J21: 9 | K21: 2.68 | L21: -1.96 | M21: 8.2 | N21: 6.38 | O21: 24.26 | P21: -4.57 | Q21: -3.63 | R21: -7.54 | S21: 3.7 | T21: 4.64 | U21: -8.73 | V21: 4.13 | W21: -8.83 | X21: -0.4 | Y21: -12.5 | Z21: 16.74 | AA21: -8.84 | AB21: -3.45 | AC21: -4.02 | AD21: -3.49 | AE21: 5.3 | AF21: -8.47 | AG21: 14.82 | AH21: -5.91 | AI21: -11.16 | AJ21: 14.66 | AK21: -2.74 | AL21: -4.51 | AM21: 2.49 | AN21: 3.41 | AO21: 1.65 | AP21: 0.69 | AQ21: 2.53 | AR21: 4.72 | AS21: 0.21 | AT21: -0.86 | AU21: 4.11 | AV21: -13.31 | AW21: 9.83 | AX21: 3.49 | AY21: -11.39 | AZ21: 15.48 | BA21: 6.56 | BB21: -10.39 | BC21: -6.13 | BD21: 17.72 | BE21: -12.33 | BF21: -1.36 | BG21: 0 | BH21: 14.71 | BI21: -4.01 | BJ21: -1.25 | BK21: 11.42 | BL21: -6.83 | BM21: 8.1 | BN21: 2.69 | BO21: -5.42
A22: A006400 | B22: 삼성SDI | C22: S310600 | D22: % | F22: 월간수익률(현금배당포함) | G22: 25.52 | H22: 1.25 | I22: 9.35 | J22: 13.84 | K22: -4.2 | L22: 1.96 | M22: 20.59 | N22: 18.02 | O22: 16.88 | P22: -8.18 | Q22: -2.08 | R22: -0.91 | S22: -5.96 | T22: 13.49 | U22: 6.16 | V22: 7.02 | W22: -9.46 | X22: 2.23 | Y22: -6.27 | Z22: -4.65 | AA22: -10.84 | AB22: -6.17 | AC22: 8.76 | AD22: 2.52 | AE22: -5.89 | AF22: -7.48 | AG22: 6.95 | AH22: 5.1 | AI22: -8.7 | AJ22: 34.98 | AK22: -1.09 | AL22: -18.79 | AM22: 15.9 | AN22: 1.6 | AO22: 5.6 | AP22: -5.99 | AQ22: 3.91 | AR22: -6.83 | AS22: -0.6 | AT22: -7.67 | AU22: -16.61 | AV22: -16.9 | AW22: 10.93 | AX22: 0.22 | AY22: -21.08 | AZ22: 1.21 | BA22: 24.93 | BB22: -7.86 | BC22: -13.71 | BD22: -5.47 | BE22: -9.75 | BF22: 10.8 | BG22: 6.92 | BH22: -13.61 | BI22: -22.17 | BJ22: -2.36 | BK22: -10.3 | BL22: 0.9 | BM22: -15.85 | BN22: -4.63 | BO22: -4.04
A23: A051910 | B23: LG화학 | C23: S310600 | D23: % | F23: 월간수익률(현금배당포함) | G23: 3.72 | H23: 25.61 | I23: 15.8 | J23: 30.28 | K23: -11.62 | L23: -6.58 | M23: 30.93 | N23: 4.27 | O23: 11.29 | P23: -9.38 | Q23: -3.13 | R23: 15.78 | S23: -12.13 | T23: 3.78 | U23: -0.94 | V23: -9.98 | W23: 2.37 | X23: 7.73 | Y23: -16.99 | Z23: -9.69 | AA23: 3.9 | AB23: -11.58 | AC23: -5.84 | AD23: -2.44 | AE23: 12.72 | AF23: -11.8 | AG23: 16.86 | AH23: 4.81 | AI23: -15.19 | AJ23: 16.79 | AK23: 18.21 | AL23: -17.57 | AM23: 15 | AN23: -1.45 | AO23: 4.7 | AP23: 3.93 | AQ23: -6.35 | AR23: -3.75 | AS23: -2.85 | AT23: -10.03 | AU23: -14.84 | AV23: -11.38 | AW23: 13.86 | AX23: 0.32 | AY23: -12.93 | AZ23: 4.26 | BA23: -3.09 | BB23: -8.32 | BC23: -12.67 | BD23: -1.71 | BE23: -11.58 | BF23: 5.24 | BG23: 10.89 | BH23: -12.06 | BI23: -9.41 | BJ23: -11.97 | BK23: -5 | BL23: -1.26 | BM23: 4.88 | BN23: -11.84 | BO23: -8.66
A24: A028260 | B24: 삼성물산 | C24: S310600 | D24: % | F24: 월간수익률(현금배당포함) | G24: -6.51 | H24: 17.05 | I24: -8.62 | J24: 1.89 | K24: -2.78 | L24: 5.24 | M24: 9.05 | N24: 16.45 | O24: -5.8 | P24: -6.54 | Q24: 2.47 | R24: 9.24 | S24: 1.84 | T24: -1.45 | U24: 3.66 | V24: -6.01 | W24: -7.14 | X24: -7.69 | Y24: -7.46 | Z24: 16.88 | AA24: -10.08 | AB24: 2.8 | AC24: 3.64 | AD24: 1.31 | AE24: 4.76 | AF24: 1.65 | AG24: -2.03 | AH24: 0 | AI24: -14.11 | AJ24: 14.49 | AK24: 2.95 | AL24: -5.15 | AM24: 4.4 | AN24: -7.09 | AO24: -1.73 | AP24: 1.29 | AQ24: 0.91 | AR24: -4.43 | AS24: -2.27 | AT24: 1.35 | AU24: 2.77 | AV24: -0.84 | AW24: 11.81 | AX24: 10.74 | AY24: 6.56 | AZ24: 13.55 | BA24: 1.15 | BB24: -5.3 | BC24: -9.99 | BD24: 5.11 | BE24: 9.36 | BF24: -4.89 | BG24: -6.7 | BH24: -15.1 | BI24: 1.71 | BJ24: -1.36 | BK24: 4.44 | BL24: 1.33 | BM24: -3.79 | BN24: 4.7 | BO24: 22.38
... A31: A035720 | B31: 카카오 | C31: S310600 | D31: % | F31: 월간수익률(현금배당포함) | G31: 43.21 | H31: 1.52 | I31: 28.41 | J31: 18.49 | K31: -10.44 | L31: -9.47 | M31: 11.51 | N31: 5.88 | O31: 13.22 | P31: 10.66 | Q31: 2.05 | R31: 13.96 | S31: 8.37 | T31: 32.52 | U31: -9.82 | V31: 5.44 | W31: -23.87 | X31: 6.36 | Y31: -2.79 | Z31: -7.74 | AA31: -24.45 | AB31: 10.7 | AC31: 13.18 | AD31: -15.59 | AE31: -5.45 | AF31: -17.77 | AG31: 7.01 | AH31: -1.87 | AI31: -22.21 | AJ31: -11.21 | AK31: 11.24 | AL31: -5.75 | AM31: 15.63 | AN31: 1.63 | AO31: -2.08 | AP31: -4.91 | AQ31: -3.27 | AR31: -12.63 | AS31: 4.48 | AT31: -6.24 | AU31: -8.63 | AV31: -13.99 | AW31: 33.6 | AX31: 7.52 | AY31: -3.32 | AZ31: 1.63 | BA31: 0.75 | BB31: -9.5 | BC31: -10.91 | BD31: -6.12 | BE31: -3.57 | BF31: -5.1 | BG31: -2.82 | BH31: 2.21 | BI31: 8.52 | BJ31: -4.74 | BK31: 0.39 | BL31: 12.52 | BM31: -9.25 | BN31: -2.17 | BO31: 11.63
A32: A329180 | B32: HD현대중공업 | C32: S310600 | D32: % | F32: 월간수익률(현금배당포함) | W32: 3.59 | X32: 1.3 | Y32: -8.98 | Z32: -10.61 | AA32: 4.31 | AB32: 10.27 | AC32: 9.13 | AD32: 17.15 | AE32: -15 | AF32: 20.17 | AG32: -12.59 | AH32: 14.8 | AI32: -19.86 | AJ32: -5.22 | AK32: 8.71 | AL32: -2.11 | AM32: -4.48 | AN32: -3.97 | AO32: -6.02 | AP32: 9.6 | AQ32: 5.93 | AR32: 13.44 | AS32: 6.07 | AT32: -6.37 | AU32: -7.34 | AV32: -15.76 | AW32: 22.62 | AX32: 3.03 | AY32: -11.55 | AZ32: 3.33 | BA32: 0.08 | BB32: 16.69 | BC32: -6.54 | BD32: 20.98 | BE32: 35.52 | BF32: -8.15 | BG32: -4.75 | BH32: -1.08 | BI32: 20.48 | BJ32: 30.68 | BK32: 8.17 | BL32: -4.15 | BM32: -5.74 | BN32: 44.08 | BO32: 0.87
A33: A000810 | B33: 삼성화재 | C33: S310600 | D33: % | F33: 월간수익률(현금배당포함) | G33: -4.2 | H33: -3.56 | I33: -2.56 | J33: 9.04 | K33: -2.67 | L33: -1.65 | M33: 5.03 | N33: 4.4 | O33: -10.4 | P33: 2.98 | Q33: 9.83 | R33: 4.21 | S33: 6.82 | T33: 4.25 | U33: -2.72 | V33: 5.36 | W33: 3.98 | X33: -1.7 | Y33: -12.56 | Z33: 5.84 | AA33: -0.74 | AB33: -4.99 | AC33: 14.96 | AD33: -4.11 | AE33: -5.24 | AF33: 1 | AG33: -1.74 | AH33: -1.27 | AI33: -5.64 | AJ33: 8.69 | AK33: 2.75 | AL33: 3.84 | AM33: 1.5 | AN33: 5.66 | AO33: -3.96 | AP33: 9.22 | AQ33: 0.22 | AR33: 1.99 | AS33: 6.09 | AT33: 1.02 | AU33: 5.68 | AV33: -0.77 | AW33: 0.58 | AX33: 1.15 | AY33: 0.38 | AZ33: 12.88 | BA33: 7.9 | BB33: 1.31 | BC33: 12.42 | BD33: 11.62 | BE33: -4.24 | BF33: -6.98 | BG33: -0.58 | BH33: -2.32 | BI33: 16.64 | BJ33: -8.66 | BK33: 6.41 | BL33: 0.26 | BM33: -1.77 | BN33: 4.75 | BO33: 8.01
A34: A259960 | B34: 크래프톤 | C34: S310600 | D34: % | F34: 월간수익률(현금배당포함) | V34: 8.26 | W34: 2.14 | X34: -6.48 | Y34: 7.13 | Z34: -8.55 | AA34: -40.33 | AB34: 7.47 | AC34: -6.61 | AD34: -8.53 | AE34: 2.98 | AF34: -15.61 | AG34: 6.62 | AH34: 5.57 | AI34: -14.81 | AJ34: -15.48 | AK34: 27.89 | AL34: -25.99 | AM34: 6.72 | AN34: -5.3 | AO34: 8.07 | AP34: 4.69 | AQ34: -1.56 | AR34: 3.01 | AS34: -11.81 | AT34: -9.78 | AU34: -2.84 | AV34: 8.76 | AW34: 30.04 | AX34: -9.11 | AY34: 10.79 | AZ34: 5.83 | BA34: 8.81 | BB34: -3.04 | BC34: 4.38 | BD34: 12.6 | BE34: 4.44 | BF34: 11.22 | BG34: 4.74 | BH34: -3.36 | BI34: -5.74 | BJ34: 0.16 | BK34: 16.48 | BL34: -5.63 | BM34: -2.62 | BN34: 11.06 | BO34: -0.67
A35: A015760 | B35: 한국전력 | C35: S310600 | D35: % | F35: 월간수익률(현금배당포함) | G35: -9.43 | H35: -9.72 | I35: -2.05 | J35: 7.33 | K35: -0.49 | L35: -2.21 | M35: 7.52 | N35: 33.62 | O35: -16.61 | P35: -0.66 | Q35: 1.98 | R35: 2.16 | S35: 9.09 | T35: -3.68 | U35: 0.2 | V35: -3.62 | W35: -1.88 | X35: -4.03 | Y35: -8.19 | Z35: 6.51 | AA35: -6.79 | AB35: 12.62 | AC35: -2.37 | AD35: 1.99 | AE35: 1.08 | AF35: -3.43 | AG35: -0.89 | AH35: -6.26 | AI35: -4.06 | AJ35: -16.67 | AK35: 23.58 | AL35: 5.31 | AM35: -8.99 | AN35: -9.02 | AO35: -0.22 | AP35: 3.72 | AQ35: 2.14 | AR35: 7.97 | AS35: -6.75 | AT35: -7.24 | AU35: 1.12 | AV35: -6.11 | AW35: 11.41 | AX35: 0.26 | AY35: 4.6 | AZ35: 25.44 | BA35: -11.29 | BB35: -3.86 | BC35: -8.04 | BD35: 0.62 | BE35: 0.92 | BF35: 9.87 | BG35: -5.3 | BH35: 12.41 | BI35: 3.46 | BJ35: -15.22 | BK35: 4.99 | BL35: 1.42 | BM35: 1.4 | BN35: 18.47 | BO35: 18.32
A36: A066570 | B36: LG전자 | C36: S310600 | D36: % | F36: 월간수익률(현금배당포함) | G36: 8.01 | H36: 6.58 | I36: 11.87 | J36: 19.09 | K36: 8.91 | L36: -8.4 | M36: 1.78 | N36: 59.33 | O36: 13.33 | P36: -4.25 | Q36: 2.39 | R36: 5 | S36: -3.49 | T36: 7.56 | U36: -3.67 | V36: -9.84 | W36: -10.21 | X36: -5.49 | Y36: -4.15 | Z36: 20.2 | AA36: -7.61 | AB36: -3.14 | AC36: -2.43 | AD36: -3.32 | AE36: -9.87 | AF36: -15.91 | AG36: 6.91 | AH36: 6.99 | AI36: -22.18 | AJ36: 3.82 | AK36: 19.61 | AL36: -10.68 | AM36: 15.72 | AN36: 11.09 | AO36: 3.69 | AP36: -5.2 | AQ36: 12.35 | AR36: 3.17 | AS36: -14.44 | AT36: -9.13 | AU36: 2.44 | AV36: -1.19 | AW36: 3.01 | AX36: -0.08 | AY36: -8.15 | AZ36: 1.5 | BA36: 0.21 | BB36: -2.31 | BC36: 12.81 | BD36: 6.3 | BE36: -6.22 | BF36: -4.42 | BG36: 4.93 | BH36: -14.19 | BI36: 0.22 | BJ36: -6.91 | BK36: 0.84 | BL36: -6.3 | BM36: -1.54 | BN36: -7.51 | BO36: -0.42
A37: A033780 | B37: KT&G | C37: S310600 | D37: % | F37: 월간수익률(현금배당포함) | G37: 3.45 | H37: -6.79 | I37: 3.45 | J37: 2.72 | K37: -0.84 | L37: -1.7 | M37: 1.85 | N37: 6.53 | O37: -3.49 | P37: -2.37 | Q37: 3.96 | R37: 1.23 | S37: 2.3 | T37: 0.12 | U37: -2.49 | V37: -0.85 | W37: -0.49 | X37: -0.12 | Y37: 0.99 | Z37: 2.27 | AA37: -1.77 | AB37: 2.83 | AC37: 1.13 | AD37: 2.35 | AE37: 2.9 | AF37: -3.3 | AG37: -0.37 | AH37: 1.59 | AI37: 4.09 | AJ37: 10.51 | AK37: 4.39 | AL37: -3.4 | AM37: 1.09 | AN37: -4.11 | AO37: -5.41 | AP37: 2.26 | AQ37: -2.57 | AR37: 0.49 | AS37: -0.24 | AT37: 5.2 | AU37: -0.69 | AV37: -1.16 | AW37: 3.4 | AX37: 3.12 | AY37: 4.26 | AZ37: 2.65 | BA37: 0.54 | BB37: -4.39 | BC37: -6.6 | BD37: 7.1 | BE37: 5.78 | BF37: 15.97 | BG37: 0.65 | BH37: 0.73 | BI37: 11.03 | BJ37: -12.07 | BK37: 3.27 | BL37: -7.39 | BM37: 2.85 | BN37: 13.45 | BO37: 4.79
A38: A009540 | B38: HD한국조선해양 | C38: S310600 | D38: % | F38: 월간수익률(현금배당포함) | G38: 9.79 | H38: -3.75 | I38: 2.06 | J38: -3.36 | K38: -4.06 | L38: -5.2 | M38: 31.38 | N38: 5.34 | O38: -13.36 | P38: 19.15 | Q38: 19.2 | R38: 14.98 | S38: -7.17 | T38: -5.97 | U38: -2.61 | V38: -9.2 | W38: -13.92 | X38: 0.98 | Y38: -15.05 | Z38: 8.11 | AA38: -15.75 | AB38: 10.66 | AC38: 0.79 | AD38: 3.26 | AE38: -0.44 | AF38: 2.73 | AG38: -9.8 | AH38: 14.76 | AI38: -25 | AJ38: -0.28 | AK38: 7.7 | AL38: -9.71 | AM38: 12.59 | AN38: 2.13 | AO38: -4.68 | AP38: 9.42 | AQ38: 13.44 | AR38: 21.1 | AS38: 5.84 | AT38: 0.32 | AU38: -10.27 | AV38: -18.65 | AW38: 23.7 | AX38: 8.24 | AY38: -6.12 | AZ38: -1.41 | BA38: 5.81 | BB38: 11.06 | BC38: -0.84 | BD38: 21.78 | BE38: 30.35 | BF38: -7.54 | BG38: -1.93 | BH38: -2.29 | BI38: 11.5 | BJ38: 11.49 | BK38: 1.75 | BL38: -5.59 | BM38: -6.08 | BN38: 35.32 | BO38: 16.36
A39: A034020 | B39: 두산에너빌리티 | C39: S310600 | D39: % | F39: 월간수익률(현금배당포함) | G39: 7.13 | H39: 12.97 | I39: 117.16 | J39: 53.33 | K39: -17.39 | L39: 12.55 | M39: 21.82 | N39: -19.4 | O39: -12.96 | P39: -9.79 | Q39: 22.64 | R39: 7.31 | S39: 42.65 | T39: 19.85 | U39: -8.81 | V39: -3.91 | W39: -1.68 | X39: 18.73 | Y39: -22.13 | Z39: 11.24 | AA39: -13.24 | AB39: 17.51 | AC39: -1.68 | AD39: 0.73 | AE39: 0.73 | AF39: -6.51 | AG39: -3.35 | AH39: 8.53 | AI39: -29.98 | AJ39: -7.02 | AK39: 26.41 | AL39: -8.06 | AM39: 8.44 | AN39: -2.64 | AO39: 4.55 | AP39: -1.82 | AQ39: -3.66 | AR39: 12.62 | AS39: -3.42 | AT39: 4.17 | AU39: -9.83 | AV39: -18.32 | AW39: 17.73 | AX39: 0.63 | AY39: -2.89 | AZ39: 5.18 | BA39: 6.03 | BB39: -2.44 | BC39: 23.81 | BD39: -3.37 | BE39: -6.32 | BF39: -3.88 | BG39: -1.05 | BH39: 11.95 | BI39: 5.49 | BJ39: -17.02 | BK39: 36.18 | BL39: 6.28 | BM39: -7.68 | BN39: 23.45 | BO39: 39.38
A40: A011200 | B40: HMM | C40: S310600 | D40: % | F40: 월간수익률(현금배당포함) | G40: 30.89 | H40: -0.85 | I40: 25.51 | J40: -2.04 | K40: 25.17 | L40: 24.41 | M40: 48.83 | N40: 4.49 | O40: -2.15 | P40: 39.19 | Q40: 52.63 | R40: 35.17 | S40: 22.19 | T40: -8.35 | U40: -8.88 | V40: 5 | W40: -19.76 | X40: -20.92 | Y40: -11.45 | Z40: 16.46 | AA40: -18.59 | AB40: 31.73 | AC40: 1.04 | AD40: -2.57 | AE40: 14.26 | AF40: -24.19 | AG40: 1.02 | AH40: -10.46 | AI40: -16.85 | AJ40: 3.24 | AK40: 16.75 | AL40: -7.1 | AM40: 11.25 | AN40: 3.68 | AO40: -9.76 | AP40: 0.24 | AQ40: -12.99 | AR40: 6.2 | AS40: -7.22 | AT40: -4.75 | AU40: -2.4 | AV40: -10.39 | AW40: 6.31 | AX40: 30.94 | AY40: -1.48 | AZ40: -5.29 | BA40: -13.96 | BB40: 0.83 | BC40: 13.56 | BD40: 9.05 | BE40: -7.29 | BF40: -6.76 | BG40: 9.19 | BH40: -7.61 | BI40: 4.91 | BJ40: -1.67 | BK40: 7.81 | BL40: 5.84 | BM40: -0.15 | BN40: -6.65 | BO40: 16.65
A41: A017670 | B41: SK텔레콤 | C41: S310600 | D41: % | F41: 월간수익률(현금배당포함) | G41: 2.13 | H41: -1.84 | I41: 4.5 | J41: 12.47 | K41: -4.03 | L41: -10.08 | M41: 10.98 | N41: 4.01 | O41: 2.52 | P41: 1.43 | Q41: 11.11 | R41: 10.36 | S41: 4.45 | T41: 1.73 | U41: -5.94 | V41: -1 | W41: 9.58 | X41: -4.48 | Y41: -11.95 | Z41: 9.26 | AA41: -2.59 | AB41: -3.19 | AC41: 5.75 | AD41: 0.17 | AE41: 0.17 | AF41: -7.51 | AG41: 3.08 | AH41: -2.8 | AI41: -0.88 | AJ41: -1.38 | AK41: -0.2 | AL41: -3.57 | AM41: -1.69 | AN41: -3.11 | AO41: 8.83 | AP41: -1.24 | AQ41: 4.19 | AR41: -4.56 | AS41: -1.07 | AT41: 4.23 | AU41: 9.96 | AV41: -5.48 | AW41: 6.2 | AX41: -1.98 | AY41: 0.2 | AZ41: 4.98 | BA41: 1.17 | BB41: -2.29 | BC41: -0.59 | BD41: 2.61 | BE41: 5.05 | BF41: 2.03 | BG41: 2.75 | BH41: 1.43 | BI41: 8.29 | BJ41: -10.1 | BK41: 0.36 | BL41: 2.97 | BM41: -0.89 | BN41: -2.16 | BO41: -3.62
A42: A003550 | B42: LG | C42: S310600 | D42: % | F42: 월간수익률(현금배당포함) | G42: 1.77 | H42: 12.84 | I42: 3.93 | J42: 11.76 | K42: -10.4 | L42: -8.5 | M42: 4.13 | N42: 27.54 | O42: 13.26 | P42: -5.25 | Q42: -3.73 | R42: 39.93 | S42: -20.16 | T42: 1.48 | U42: -8.1 | V42: 1.17 | W42: -2.41 | X42: -1.94 | Y42: -14.04 | Z42: 6.72 | AA42: -8.53 | AB42: 1.62 | AC42: 1.59 | AD42: -4.06 | AE42: 9.41 | AF42: -2.87 | AG42: 4.11 | AH42: 1.11 | AI42: -9.76 | AJ42: 7.03 | AK42: 6.19 | AL42: -3.63 | AM42: 6.02 | AN42: -0.6 | AO42: 0.61 | AP42: 5.55 | AQ42: -1.6 | AR42: 2.32 | AS42: -5.11 | AT42: -1.68 | AU42: 2.07 | AV42: -7.88 | AW42: 8.94 | AX42: 5.95 | AY42: -4.54 | AZ42: 14.27 | BA42: -6.62 | BB42: -9.26 | BC42: 2.39 | BD42: -0.86 | BE42: 7.57 | BF42: -8.65 | BG42: -0.13 | BH42: -4.3 | BI42: -1.06 | BJ42: -3.87 | BK42: 4.03 | BL42: -11.22 | BM42: 1.6 | BN42: 3.09 | BO42: 6.61
A43: A267260 | B43: HD현대일렉트릭 | C43: S310600 | D43: % | F43: 월간수익률(현금배당포함) | G43: 0.24 | H43: -4.23 | I43: 57.2 | J43: -5.62 | K43: 30.21 | L43: -1.96 | M43: 8 | N43: 1.23 | O43: 2.13 | P43: 5.37 | Q43: 18.7 | R43: 5.25 | S43: -0.68 | T43: -5.94 | U43: 14.32 | V43: 5.94 | W43: 11.42 | X43: -20.5 | Y43: -1.36 | Z43: -8.72 | AA43: -12.31 | AB43: 16.9 | AC43: 5.15 | AD43: 1.86 | AE43: 3.2 | AF43: 12.42 | AG43: 8.28 | AH43: 16.39 | AI43: -0.31 | AJ43: 7.85 | AK43: 22.41 | AL43: 2.22 | AM43: -5.77 | AN43: 4.99 | AO43: -9.87 | AP43: 33.51 | AQ43: -3.36 | AR43: 33.13 | AS43: 14.13 | AT43: -5.25 | AU43: -5.4 | AV43: 12.61 | AW43: 12.13 | AX43: -1.04 | AY43: 24.94 | AZ43: 21.13 | BA43: 44.21 | BB43: 37.68 | BC43: 21.86 | BD43: 2.99 | BE43: 0 | BF43: -1.45 | BG43: 8.23 | BH43: -0.61 | BI43: 6.72 | BJ43: 9.3 | BK43: 7.33 | BL43: -19.75 | BM43: -10.29 | BN43: 5.31 | BO43: 23.25
A44: A316140 | B44: 우리금융지주 | C44: S310600 | D44: % | F44: 월간수익률(현금배당포함) | G44: 8.17 | H44: -3.51 | I44: -3.52 | J44: -0.47 | K44: 1.42 | L44: 3.61 | M44: 10.57 | N44: 2.66 | O44: -9.56 | P44: 8.86 | Q44: 5.43 | R44: 5.94 | S44: 4.2 | T44: 2.69 | U44: -3.95 | V44: 3.69 | W44: 3.55 | X44: 13.73 | Y44: -4.91 | Z44: 6.68 | AA44: 15.35 | AB44: -2.39 | AC44: 7.34 | AD44: -3.91 | AE44: 1.02 | AF44: -17.78 | AG44: -1.65 | AH44: 2.52 | AI44: -12.3 | AJ44: 9.81 | AK44: 10.64 | AL44: -3.78 | AM44: 10.73 | AN44: -4.61 | AO44: -6.48 | AP44: 2.8 | AQ44: 2.13 | AR44: -0.06 | AS44: -1.19 | AT44: 2.23 | AU44: 4.45 | AV44: -2.94 | AW44: 9.41 | AX44: -0.15 | AY44: 6.77 | AZ44: 12.08 | BA44: -2.71 | BB44: -0.63 | BC44: -0.42 | BD44: 4.96 | BE44: 7.15 | BF44: 1.78 | BG44: -2.15 | BH44: -0.45 | BI44: 8.29 | BJ44: -8.02 | BK44: 4.75 | BL44: 6.98 | BM44: -0.48 | BN44: 7.33 | BO44: 10.04
A45: A402340 | B45: SK스퀘어 | C45: S310600 | D45: % | F45: 월간수익률(현금배당포함) | Y45: -10.53 | Z45: -2.35 | AA45: -17.17 | AB45: 1.45 | AC45: 1.79 | AD45: -7.22 | AE45: -10.25 | AF45: -17.44 | AG45: 9.47 | AH45: -5.26 | AI45: -10.74 | AJ45: 2.21 | AK45: 1.35 | AL45: -10.41 | AM45: 8.05 | AN45: 5.79 | AO45: 3.65 | AP45: 6.79 | AQ45: 8.72 | AR45: -4.12 | AS45: 0.34 | AT45: 1.58 | AU45: -5.88 | AV45: 0.23 | AW45: 19.86 | AX45: 3.14 | AY45: -1.33 | AZ45: 34.68 | BA45: 13.02 | BB45: -3.17 | BC45: 1.44 | BD45: 28.86 | BE45: -13.8 | BF45: -8.93 | BG45: 2.93 | BH45: 4.95 | BI45: -13.33 | BJ45: 7.89 | BK45: 18.66 | BL45: -4.25 | BM45: 3.66 | BN45: -4.82 | BO45: 29.13
A46: A024110 | B46: 기업은행 | C46: S310600 | D46: % | F46: 월간수익률(현금배당포함) | G46: 4.81 | H46: -2.42 | I46: 0.37 | J46: -0.25 | K46: -0.99 | L46: 2 | M46: 13.83 | N46: 0.09 | O46: -11.43 | P46: 6.38 | Q46: 9.96 | R46: 5.78 | S46: 11.45 | T46: -2.78 | U46: -1.91 | V46: 0 | W46: 1.94 | X46: 5.24 | Y46: -6.79 | Z46: 7.46 | AA46: 0.48 | AB46: 3.86 | AC46: 0.93 | AD46: 3.69 | AE46: 0 | AF46: -14.49 | AG46: -2.39 | AH46: 1.92 | AI46: -0.52 | AJ46: 9.77 | AK46: 7.18 | AL46: -3.91 | AM46: 4.38 | AN46: 1.27 | AO46: -2.7 | AP46: -0.4 | AQ46: 1.49 | AR46: 1.27 | AS46: 0.48 | AT46: 3.56 | AU46: 4.18 | AV46: -0.36 | AW46: 5.91 | AX46: 0.25 | AY46: 5.56 | AZ46: 11.82 | BA46: 3.23 | BB46: 3.33 | BC46: -1.36 | BD46: 1.89 | BE46: -0.14 | BF46: -1.36 | BG46: 1.16 | BH46: 0.93 | BI46: 5.53 | BJ46: -3.7 | BK46: 8.37 | BL46: 0.39 | BM46: -2.11 | BN46: 7.87 | BO46: 2.61
A47: A096770 | B47: SK이노베이션 | C47: S310600 | D47: % | F47: 월간수익률(현금배당포함) | G47: 20.55 | H47: 10.55 | I47: -3.05 | J47: 14.17 | K47: -4.14 | L47: -9.71 | M47: 37.85 | N47: 9.83 | O47: 47.37 | P47: -6.97 | Q47: -15.93 | R47: 23.51 | S47: -2.03 | T47: 11.51 | U47: -14.38 | V47: -1.38 | W47: 6.21 | X47: -8.49 | Y47: -19.79 | Z47: 22.62 | AA47: -9.43 | AB47: -7.18 | AC47: 7.23 | AD47: -4.65 | AE47: 5.12 | AF47: -10.91 | AG47: -2.34 | AH47: 1.33 | AI47: -24.47 | AJ47: 20.56 | AK47: 3.47 | AL47: -13.97 | AM47: 5.26 | AN47: -7.4 | AO47: 19.45 | AP47: -3.46 | AQ47: 9.24 | AR47: -16.18 | AS47: 36.28 | AT47: -16.48 | AU47: -16.17 | AV47: -17.88 | AW47: 17.1 | AX47: -1.96 | AY47: -16.54 | AZ47: 0 | BA47: -0.94 | BB47: -4.23 | BC47: -9.99 | BD47: 16.1 | BE47: -10.25 | BF47: 5.57 | BG47: 6.45 | BH47: 0.26 | BI47: -2.39 | BJ47: -2.27 | BK47: 13.84 | BL47: -1.41 | BM47: -10.58 | BN47: -14.49 | BO47: -5.19
...

Sheet FlMktcap
A1: Refresh | B1: Last Update : 2025-06-19 08:32:35
A2: 0
A3: Time Series (Company)
A4: Frequency | B4: M | C4: Ascending | D4: 0
A5: Period(From) | B5: 20200401 | C5: Korean | D5: 0
A6: Period(To) | B6: 20250430 | D6: 0
A8: Code | B8: Name | C8: Item Code | D8: Unit | E8: Base Date | G8: 43950 | H8: 43980 | I8: 44012 | J8: 44043 | K8: 44074 | L8: 44103 | M8: 44134 | N8: 44165 | O8: 44195 | P8: 44225 | Q8: 44253 | R8: 44286 | S8: 44316 | T8: 44347 | U8: 44377 | V8: 44407 | W8: 44439 | X8: 44469 | Y8: 44498 | Z8: 44530 | AA8: 44560 | AB8: 44589 | AC8: 44620 | AD8: 44651 | AE8: 44680 | AF8: 44712 | AG8: 44742 | AH8: 44771 | AI8: 44804 | AJ8: 44834 | AK8: 44865 | AL8: 44895 | AM8: 44924 | AN8: 44957 | AO8: 44985 | AP8: 45016 | AQ8: 45044 | AR8: 45077 | AS8: 45107 | AT8: 45138 | AU8: 45169 | AV8: 45196 | AW8: 45230 | AX8: 45260 | AY8: 45288 | AZ8: 45322 | BA8: 45351 | BB8: 45380 | BC8: 45412 | BD8: 45443 | BE8: 45471 | BF8: 45504 | BG8: 45534 | BH8: 45565 | BI8: 45596 | BJ8: 45625 | BK8: 45656 | BL8: 45688 | BM8: 45716 | BN8: 45747 | BO8: 45777
A9: IKS200 | B9: 코스피 200 | C9: S102306 | D9: KRW bil | F9: 유동시가총액 | G9: 709426.04 | H9: 737363.29 | I9: 779309.5 | J9: 831609.01 | K9: 852777.44 | L9: 861115.63 | M9: 842702.77 | N9: 966882.03 | O9: 1102542 | P9: 1151962 | Q9: 1168459.7 | R9: 1183899.4 | S9: 1209133.9 | T9: 1222314.5 | U9: 1264867.7 | V9: 1223717.7 | W9: 1214434.3 | X9: 1183963.9 | Y9: 1148272.2 | Z9: 1105375.4 | AA9: 1178210.6 | AB9: 1070556.8 | AC9: 1093070.3 | AD9: 1123415.3 | AE9: 1091651.7 | AF9: 1091415.1 | AG9: 953054.95 | AH9: 1003207.6 | AI9: 1003822.4 | AJ9: 876648.54 | AK9: 936142.34 | AL9: 1004019.8 | AM9: 909317.88 | AN9: 991842.71 | AO9: 985855.55 | AP9: 1011031.3 | AQ9: 1026356.9 | AR9: 1064025 | AS9: 1063802.6 | AT9: 1086558.5 | AU9: 1053124.5 | AV9: 1027584.3 | AW9: 959946.18 | AX9: 1064016.1 | AY9: 1130317.1 | AZ9: 1072740.9 | BA9: 1138356.8 | BB9: 1201994.7 | BC9: 1171167.9 | BD9: 1149481.1 | BE9: 1247659.2 | BF9: 1236549.3 | BG9: 1175952.5 | BH9: 1126128.1 | BI9: 1104078 | BJ9: 1058968.5 | BK9: 1032537.5 | BL9: 1080491.1 | BM9: 1082384.3 | BN9: 1073578.9 | BO9: 1093309.4
A10: =Ret!A10 -> A005930 | B10: 삼성전자 | C10: S102306 | D10: KRW bil | F10: 유동시가총액 | G10: 223269.87 | H10: 226335.11 | I10: 235520.82 | J10: 257820.64 | K10: 240357.77 | L10: 259191.24 | M10: 252268.44 | N10: 297324.36 | O10: 360826.79 | P10: 365673.06 | Q10: 367853.52 | R10: 362948.81 | S10: 363297.39 | T10: 358695.58 | U10: 359490.4 | V10: 349643.3 | W10: 341946.52 | X10: 330222.4 | Y10: 311018.03 | Z10: 317531.54 | AA10: 348752.49 | AB10: 326876.04 | AC10: 321653.85 | AD10: 312162.8 | AE10: 302456.53 | AF10: 302697.94 | AG10: 256535.29 | AH10: 276338.01 | AI10: 268758.24 | AJ10: 239299.87 | AK10: 268365.13 | AL10: 281201 | AM10: 250171.74 | AN10: 275994.39 | AO10: 274184.59 | AP10: 289644.3 | AQ10: 296471.94 | AR10: 323262.29 | AS10: 327013.58 | AT10: 316185 | AU10: 303168.18 | AV10: 310088.18 | AW10: 303327.93 | AX10: 330209.21 | AY10: 356250.95 | AZ10: 331969.04 | BA10: 335253.08 | BB10: 376557.17 | BC10: 354673.74 | BD10: 336280.24 | BE10: 372346.98 | BF10: 383161.54 | BG10: 338920.26 | BH10: 280606.35 | BI10: 270041.44 | BJ10: 246748.54 | BK10: 241338.49 | BL10: 237021.14 | BM10: 246162.19 | BN10: 260003.64 | BO10: 248868.98
A11: =Ret!A11 -> A000660 | B11: SK하이닉스 | C11: S102306 | D11: KRW bil | F11: 유동시가총액 | G11: 44871.65 | H11: 43603.23 | I11: 45461.11 | J11: 44238.46 | K11: 40173.7 | L11: 44983.56 | M11: 42793.75 | N11: 52340.82 | O11: 63605.6 | P11: 65770.46 | Q11: 75909.79 | R11: 71062.31 | S11: 68676.83 | T11: 68639.56 | U11: 68473.54 | V11: 60409.64 | W11: 57195.54 | X11: 55323.37 | Y11: 55330.87 | Z11: 61240 | AA11: 70381.81 | AB11: 64740.52 | AC11: 66361.31 | AD11: 63405.95 | AE11: 60450.59 | AF11: 58032.56 | AG11: 48904.43 | AH11: 52612.57 | AI11: 51161.56 | AJ11: 44658.88 | AK11: 44455.96 | AL11: 45692.34 | AM11: 40316.77 | AN11: 47560.9 | AO11: 48077.12 | AP11: 47653.35 | AQ11: 48137.41 | AR11: 58402.4 | AS11: 61909.79 | AT11: 66361.48 | AU11: 65501.04 | AV11: 61666.13 | AW11: 62517.87 | AX11: 71978.88 | AY11: 76033.4 | AZ11: 72408.92 | BA11: 84091.48 | BB11: 98466.18 | BC11: 93794.6 | BD11: 101857.29 | BE11: 127304.39 | BF11: 104920.25 | BG11: 93651.84 | BH11: 94213.35 | BI11: 100499.49 | BJ11: 86234.73 | BK11: 93759.67 | BL11: 107443.89 | BM11: 102769.5 | BN11: 103025.78 | BO11: 95907.4
A12: =Ret!A12 -> A373220 | B12: LG에너지솔루션 | C12: S102306 | D12: KRW bil | F12: 유동시가총액 | AB12: 15458.04 | AC12: 14152.69 | AD12: 15214.26 | AE12: 14353.72 | AF12: 15283.1 | AG12: 12796.38 | AH12: 14555.46 | AI12: 15952.37 | AJ12: 14750.59 | AK12: 18260.99 | AL12: 20301.51 | AM12: 15072.05 | AN12: 18031.08 | AO12: 18100.3 | AP12: 23217.85 | AQ12: 23098.58 | AR12: 23814.2 | AS12: 22412.43 | AT12: 22696.13 | AU12: 22047.67 | AV12: 19311.97 | AW12: 15714.06 | AX12: 18526.69 | AY12: 17426.1 | AZ12: 15584.12 | BA12: 16422.63 | BB12: 16156.76 | BC12: 15911.34 | BD12: 13538.96 | BE12: 13354.89 | BF12: 13313.29 | BG12: 15943.08 | BH12: 17031.97 | BI12: 16744.34 | BJ12: 15675.99 | BK12: 14299.46 | BL12: 14463.82 | BM12: 14463.82 | BN12: 13744.74 | BO12: 13333.83
A13: =Ret!A13 -> A207940 | B13: 삼성바이오로직스 | C13: S102306 | D13: KRW bil | F13: 유동시가총액 | G13: 9545.12 | H13: 10218.69 | I13: 12742.55 | J13: 12051.99 | K13: 12791.88 | L13: 11349.55 | M13: 11217.96 | N13: 12928.61 | O13: 13586.56 | P13: 13049 | Q13: 12341.43 | R13: 12308.52 | S13: 13224.69 | T13: 13910.26 | U13: 13849.98 | V13: 14662.83 | W13: 15904.84 | X13: 14405.01 | Y13: 14355.56 | Z13: 14652.23 | AA13: 14882.98 | AB13: 12179.98 | AC13: 14182.71 | AD13: 15062.5 | AE13: 15262.85 | AF13: 15426.77 | AG13: 13905.05 | AH13: 15225.15 | AI13: 14691.17 | AJ13: 14210.02 | AK13: 15436.37 | AL13: 15625.01 | AM13: 14462.38 | AN13: 13974.79 | AO13: 13622.33 | AP13: 13892.28 | AQ13: 13768.87 | AR13: 13821.76 | AS13: 13286.02 | AT13: 13673.44 | AU13: 13155.77 | AV13: 12156.15 | AW13: 12696.33 | AX13: 12982.85 | AY13: 13615.02 | AZ13: 15066.11 | BA13: 13882.35 | BB13: 14904.69 | BC13: 14102.4 | BD13: 13181.5 | BE13: 13127.33 | BF13: 16944 | BG13: 17702.68 | BH13: 17648.49 | BI13: 18100.09 | BJ13: 17612.36 | BK13: 17142.7 | BL13: 19527.14 | BM13: 20167.32 | BN13: 18324.07 | BO13: 19010.77
A14: =Ret!A14 -> A005380 | B14: 현대차 | C14: S102306 | D14: KRW bil | F14: 유동시가총액 | G14: 12809.58 | H14: 13411.74 | I14: 13370.68 | J14: 17312.09 | K14: 24158.59 | L14: 24432.34 | M14: 22502.02 | N14: 24749.89 | O14: 26280.16 | P14: 31344.57 | Q14: 32444.64 | R14: 29685.22 | S14: 28868.2 | T14: 32000.12 | U14: 32612.89 | V14: 29685.22 | W14: 28936.28 | X14: 27259.79 | Y14: 28350.18 | Z14: 26575.43 | AA14: 28218.54 | AB14: 25435.89 | AC14: 23437.26 | AD14: 24173.86 | AE14: 24910.46 | AF14: 25379.21 | AG14: 24189.29 | AH14: 26266.49 | AI14: 26266.49 | AJ14: 24045.45 | AK14: 22621.52 | AL14: 23240.35 | AM14: 20765.04 | AN14: 22797.6 | AO14: 24065.18 | AP14: 25297.67 | AQ14: 27080.16 | AR14: 27422.94 | AS14: 28266.14 | AT14: 26828.88 | AU14: 25884.39 | AV14: 26158.16 | AW14: 23228.88 | AX14: 25402.79 | AY14: 28049.2 | AZ14: 26661.94 | BA14: 34341.94 | BB14: 31942.8 | BC14: 34413.3 | BD14: 34687.51 | BE14: 40439.73 | BF14: 34196.45 | BG14: 35089.13 | BH14: 34015.64 | BI14: 29972.8 | BJ14: 30442.42 | BK14: 29350.35 | BL14: 28196.13 | BM14: 26154.05 | BN14: 26723.21 | BO14: 25828.82
A15: =Ret!A15 -> A068270 | B15: 셀트리온 | C15: S102306 | D15: KRW bil | F15: 유동시가총액 | G15: 21456.84 | H15: 21805.95 | I15: 31290.66 | J15: 30319.22 | K15: 30398.62 | L15: 26355.7 | M15: 24683.16 | N15: 34823.76 | O15: 37518.36 | P15: 33905.18 | Q15: 31142.94 | R15: 33938.08 | S15: 27830.8 | T15: 28768.36 | U15: 28146.95 | V15: 26574.5 | W15: 30719.34 | X15: 27160.53 | Y15: 20985.3 | Z15: 21659.01 | AA15: 21130.47 | AB15: 16059.42 | AC15: 16928.54 | AD15: 18124.95 | AE15: 18570.82 | AF15: 16926.86 | AG15: 18774.94 | AH15: 19973.83 | AI15: 19922 | AJ15: 18452.66 | AK15: 20187.53 | AL15: 18506.99 | AM15: 17551.84 | AN15: 17679.23 | AO15: 15837.73 | AP15: 16293.44 | AQ15: 17444.64 | AR15: 18614.47 | AS15: 16563.54 | AT15: 15833.85 | AU15: 15530.86 | AV15: 14940.04 | AW15: 15846.34 | AX15: 16885.1 | AY15: 20809.41 | AZ15: 26119.31 | BA15: 26131.5 | BB15: 27724.59 | BC15: 27372.62 | BD15: 25483.1 | BE15: 25178.05 | BF15: 29509.45 | BG15: 29283.56 | BH15: 28187.23 | BI15: 26306.55 | BJ15: 26832.43 | BK15: 28174.72 | BL15: 26951.25 | BM15: 27514.57 | BN15: 25184.33 | BO15: 23904.51
A16: =Ret!A16 -> A000270 | B16: 기아 | C16: S102306 | D16: KRW bil | F16: 유동시가총액 | G16: 7255.88 | H16: 8381.59 | I16: 7844.51 | J16: 9888.24 | K16: 10389.99 | L16: 11479.17 | M16: 12362.35 | N16: 14149.38 | O16: 15315.92 | P16: 20249.42 | Q16: 19488.53 | R16: 20771.02 | S16: 19292.74 | T16: 21447.52 | U16: 22536.9 | V16: 21027.74 | W16: 21405.03 | X16: 20440.53 | Y16: 21415.38 | Z16: 19584.64 | AA16: 20725.58 | AB16: 20675.15 | AC16: 18607.64 | AD16: 18412.09 | AE16: 20850.45 | AF16: 21323.19 | AG16: 19245.7 | AH16: 20216.7 | AI16: 20117.11 | AJ16: 17907.07 | AK16: 16480.11 | AL16: 17085.19 | AM16: 14768.98 | AN16: 16631.47 | AO16: 18430.31 | AP16: 19641.56 | AQ16: 20558.77 | AR16: 20897.49 | AS16: 21611.85 | AT16: 20195.48 | AU16: 19584.97 | AV16: 19878.01 | AW16: 18779.11 | AX16: 21073.62 | AY16: 24532.74 | AZ16: 24818.07 | BA16: 29702.34 | BB16: 26175.55 | BC16: 28028.27 | BD16: 27960.33 | BE16: 30715.98 | BF16: 26800.35 | BG16: 25365.89 | BH16: 23883.63 | BI16: 21971.02 | BJ16: 22384.24 | BK16: 24263.65 | BL16: 24576.88 | BM16: 22456.53 | BN16: 22188.28 | BO16: 21580.55
A17: =Ret!A17 -> A105560 | B17: KB금융 | C17: S102306 | D17: KRW bil | F17: 유동시가총액 | G17: 11065.29 | H17: 10836.37 | I17: 10799.26 | J17: 11239.16 | K17: 11744.71 | L17: 11978.74 | M17: 12783.88 | N17: 14401.01 | O17: 13785.39 | P17: 12740.39 | Q17: 13896.05 | R17: 17904.87 | S17: 17433.81 | T17: 18725.88 | U17: 17768.15 | V17: 16328.84 | W17: 16838.12 | X17: 17572.15 | Y17: 17978.18 | Z17: 16775.55 | AA17: 17620.9 | AB17: 19077.45 | AC17: 19134.13 | AD17: 19716.22 | AE17: 18832.53 | AF17: 19441.69 | AG17: 15605.85 | AH17: 15685.1 | AI17: 15969.72 | AJ17: 14123.5 | AK17: 15543.14 | AL17: 16995.5 | AM17: 15732.34 | AN17: 18036.73 | AO17: 16428.73 | AP17: 15090.32 | AQ17: 15673.44 | AR17: 15184.93 | AS17: 15094.28 | AT17: 16082.54 | AU17: 17047.01 | AV17: 17371.58 | AW17: 16005.39 | AX17: 16202.63 | AY17: 16728.29 | AZ17: 17594.96 | BA17: 20067.9 | BB17: 21997.73 | BC17: 23785.09 | BD17: 24890.93 | BE17: 24634.13 | BF17: 27871.24 | BG17: 27212.82 | BH17: 25558.3 | BI17: 28360.98 | BJ17: 30176.16 | BK17: 25968.31 | BL17: 28659.94 | BM17: 24259.29 | BN17: 24162.17 | BO17: 27538
A18: =Ret!A18 -> A005490 | B18: POSCO홀딩스 | C18: S102306 | D18: KRW bil | F18: 유동시가총액 | G18: 11160.45 | H18: 10874.56 | I18: 10429.73 | J18: 11564.83 | K18: 11118.62 | L18: 11801.4 | M18: 12351.65 | N18: 13660.99 | O18: 15713.44 | P18: 14334.51 | Q18: 16392.33 | R18: 18466.87 | S18: 21094.92 | T18: 20684.77 | U18: 20461.98 | V18: 21594.5 | W18: 19894.53 | X18: 19648.16 | Y18: 17613.48 | Z18: 15508.05 | AA18: 16300.62 | AB18: 15736.48 | AC18: 16971.35 | AD18: 17335.34 | AE18: 17101.2 | AF18: 17108.76 | AG18: 13868.64 | AH18: 14569.01 | AI18: 15349.42 | AJ18: 12701.74 | AK18: 14997.68 | AL18: 18082.43 | AM18: 16700.81 | AN18: 18160.6 | AO18: 19228.96 | AP18: 22323.96 | AQ18: 23070.79 | AR18: 22100.49 | AS18: 23898.17 | AT18: 39749.17 | AU18: 36651.61 | AV18: 33821.09 | AW18: 25989.43 | AX18: 30909.61 | AY18: 31914.84 | AZ18: 27121.38 | BA18: 27508.04 | BB18: 26902.41 | BC18: 25815.24 | BD18: 23523.67 | BE18: 23141.17 | BF18: 22345.63 | BG18: 21605.78 | BH18: 24503.54 | BI18: 21597.02 | BJ18: 18213.28 | BK18: 16490.22 | BL18: 16941.27 | BM18: 17748.69 | BN18: 18045.14 | BO18: 17054.07
A19: =Ret!A19 -> A035420 | B19: NAVER | C19: S102306 | D19: KRW bil | F19: 유동시가총액 | G19: 24642.96 | H19: 28169.33 | I19: 33174.44 | J19: 37453.29 | K19: 40144.41 | L19: 37146.61 | M19: 36851.51 | N19: 35632.3 | O19: 37572.79 | P19: 44149.86 | Q19: 48712.31 | R19: 49554.23 | S19: 47419.31 | T19: 47993.66 | U19: 55302.89 | V19: 57457.88 | W19: 58323.89 | X19: 52077.21 | Y19: 54627.39 | Z19: 51137.68 | AA19: 50804.15 | AB19: 41640.25 | AC19: 42714.84 | AD19: 45759.46 | AE19: 38502.45 | AF19: 38704.04 | AG19: 32729.76 | AH19: 35363.36 | AI19: 32773.07 | AJ19: 26426.46 | AK19: 23115.39 | AL19: 25501.94 | AM19: 24209.3 | AN19: 27662.24 | AO19: 28481.87 | AP19: 27610.51 | AQ19: 26284.66 | AR19: 27268.8 | AS19: 25001.14 | AT19: 31090.96 | AU19: 29378.9 | AV19: 27264.5 | AW19: 25378.18 | AX19: 28169.97 | AY19: 30340.52 | AZ19: 27193.3 | BA19: 26447.35 | BB19: 25784.85 | BC19: 25372.07 | BD19: 23418.25 | BE19: 22969.62 | BF19: 23991.97 | BG19: 23314.28 | BH19: 23355.64 | BI19: 23039.29 | BJ19: 27986.33 | BK19: 26962.63 | BL19: 29372.47 | BM19: 28083.61 | BN19: 25713.17 | BO19: 26992.1
A20: =Ret!A20 -> A055550 | B20: 신한지주 | C20: S102306 | D20: KRW bil | F20: 유동시가총액 | G20: 12119.31 | H20: 11816.63 | I20: 11249.14 | J20: 11761.55 | K20: 11584.3 | L20: 10771.5 | M20: 11853.07 | N20: 12457.49 | O20: 12399.46 | P20: 11869 | Q20: 12756.25 | R20: 14484.84 | S20: 15458.73 | T20: 16401.19 | U20: 15659.15 | V20: 15099.89 | W20: 14976.15 | X20: 15694.71 | Y20: 16355.3 | Z20: 14817.76 | AA20: 15828.45 | AB20: 16385.46 | AC20: 16769.99 | AD20: 17755.68 | AE20: 17946.68 | AF20: 18343.36 | AG20: 15879.92 | AH20: 15306.79 | AI20: 15696.43 | AJ20: 14380.7 | AK20: 15489.57 | AL20: 16206.84 | AM20: 14972.11 | AN20: 17744.93 | AO20: 16518.69 | AP20: 14945.99 | AQ20: 14798.96 | AR20: 15349.47 | AS20: 14853.34 | AT20: 15290.24 | AU20: 15412.54 | AV20: 15428.48 | AW20: 15029.65 | AX20: 15913.89 | AY20: 17265.85 | AZ20: 17624.15 | BA20: 18657.28 | BB20: 19570.08 | BC20: 19849.4 | BD20: 19970.88 | BE20: 20254.63 | BF20: 25045.62 | BG20: 23478.83 | BH20: 23224.89 | BI20: 21415.07 | BJ20: 21951.78 | BK20: 19673.52 | BL20: 20848.4 | BM20: 18558.71 | BN20: 18885.73 | BO20: 19977.11
A21: =Ret!A21 -> A012330 | B21: 현대모비스 | C21: S102306 | D21: KRW bil | F21: 유동시가총액 | G21: 10967.18 | H21: 12625.01 | I21: 12242.44 | J21: 13103.23 | K21: 14282.84 | L21: 14665.42 | M21: 14294.89 | N21: 15370.23 | O21: 16058.22 | P21: 19954.93 | Q21: 19023.44 | R21: 18240.85 | S21: 16784.63 | T21: 17387.71 | U21: 18132.9 | V21: 16531.69 | W21: 17140.39 | X21: 15583.93 | Y21: 15467.39 | Z21: 13533.84 | AA21: 15620.69 | AB21: 14239.68 | AC21: 13748.66 | AD21: 13196.26 | AE21: 12735.92 | AF21: 13411.08 | AG21: 12214.21 | AH21: 14024.86 | AI21: 13196.26 | AJ21: 11986.91 | AK21: 13782.83 | AL21: 13405.22 | AM21: 12467.29 | AN21: 12625.13 | AO21: 13055.19 | AP21: 13270.21 | AQ21: 13362.37 | AR21: 13700.27 | AS21: 14283.91 | AT21: 14305.84 | AU21: 14111.17 | AV21: 14641.61 | AW21: 12677.73 | AX21: 13968.44 | AY21: 14456.42 | AZ21: 12809.49 | BA21: 14757.84 | BB21: 15456.46 | BC21: 13788.14 | BD21: 12941.35 | BE21: 15174.31 | BF21: 13303.92 | BG21: 13122.91 | BH21: 13195.72 | BI21: 15137.16 | BJ21: 14530.46 | BK21: 14383.64 | BL21: 16025.75 | BM21: 14867.09 | BN21: 15661.61 | BO21: 15960.56
A22: =Ret!A22 -> A006400 | B22: 삼성SDI | C22: S102306 | D22: KRW bil | F22: 유동시가총액 | G22: 14462.86 | H22: 18137.15 | I22: 18361.99 | J22: 20063.08 | K22: 22842.22 | L22: 21871.17 | M22: 22293.94 | N22: 26858.22 | O22: 31593.51 | P22: 36890.84 | Q22: 33852.06 | R22: 33130.75 | S22: 32825.06 | T22: 30897.21 | U22: 35062.28 | V22: 37217.18 | W22: 39768.93 | X22: 35992.87 | Y22: 36764.65 | Z22: 34436.95 | AA22: 32780.67 | AB22: 29227.35 | AC22: 27440.73 | AD22: 29872.99 | AE22: 30620.63 | AF22: 28824.37 | AG22: 26709.05 | AH22: 28566.64 | AI22: 30026.69 | AJ22: 27415.68 | AK22: 37011.21 | AL22: 36639.54 | AM22: 29715.85 | AN22: 34432.81 | AO22: 34995.31 | AP22: 36971.42 | AQ22: 34762.92 | AR22: 36121.24 | AS22: 33656.14 | AT22: 33454.91 | AU22: 30893.41 | AV22: 25761.28 | AW22: 21447.07 | AX22: 23816.84 | AY22: 23829.83 | AZ22: 18808.94 | BA22: 19056.9 | BB22: 23811.73 | BC22: 21947.13 | BD22: 18940.83 | BE22: 17908.88 | BF22: 16165.72 | BG22: 17916.19 | BH22: 19148.34 | BI22: 16545.2 | BJ22: 12880.42 | BK22: 12527.85 | BL22: 11237.1 | BM22: 11344.5 | BN22: 9551.78 | BO22: 10152.05
A23: =Ret!A23 -> A051910 | B23: LG화학 | C23: S102306 | D23: KRW bil | F23: 유동시가총액 | G23: 17087.01 | H23: 17722.38 | I23: 22260.76 | J23: 25778.01 | K23: 33584.02 | L23: 29990.34 | M23: 28018.5 | N23: 36685.43 | O23: 38373.49 | P23: 42788.63 | Q23: 38775.74 | R23: 37562.54 | S23: 43488.55 | T23: 38215.8 | U23: 39662.31 | V23: 39289.02 | W23: 35369.45 | X23: 36209.35 | Y23: 39014.95 | Z23: 32388.01 | AA23: 28701.19 | AB23: 29821.23 | AC23: 26367.76 | AD23: 24827.69 | AE23: 24221 | AF23: 27301.13 | AG23: 24081 | AH23: 28141.16 | AI23: 29494.55 | AJ23: 25014.37 | AK23: 29214.54 | AL23: 34806.4 | AM23: 28221.41 | AN23: 32454.62 | AO23: 31984.26 | AP23: 33489.4 | AQ23: 34806.4 | AR23: 32595.72 | AS23: 31372.8 | AT23: 30479.12 | AU23: 27421.8 | AV23: 23353.21 | AW23: 20695.7 | AX23: 23564.87 | AY23: 23470.8 | AZ23: 20437 | BA23: 21307.16 | BB23: 20648.66 | BC23: 18931.86 | BD23: 16533.04 | BE23: 16250.83 | BF23: 14369.4 | BG23: 15121.97 | BH23: 16768.22 | BI23: 14732.41 | BJ23: 13217.8 | BK23: 11635.38 | BL23: 11053.61 | BM23: 10773.28 | BN23: 11245.29 | BO23: 9914.21
A24: =Ret!A24 -> A028260 | B24: 삼성물산 | C24: S102306 | D24: KRW bil | F24: 유동시가총액 | G24: 10503.97 | H24: 9819.57 | I24: 11504.99 | J24: 10517.15 | K24: 10715.58 | L24: 10417.93 | M24: 10971.89 | N24: 11967.07 | O24: 13705.03 | P24: 12920.25 | Q24: 12075.47 | R24: 12387.59 | S24: 13526.74 | T24: 13777.98 | U24: 13584.12 | V24: 14079.06 | W24: 13235.81 | X24: 12295.01 | Y24: 11349.24 | Z24: 10503.03 | AA24: 11835.9 | AB24: 10644.36 | AC24: 10942.8 | AD24: 11342.85 | AE24: 11492.1 | AF24: 12037.08 | AG24: 12077.43 | AH24: 11831.95 | AI24: 11829.7 | AJ24: 10162.71 | AK24: 11635.57 | AL24: 11979.24 | AM24: 11144.62 | AN24: 11637.79 | AO24: 10812.83 | AP24: 10630.28 | AQ24: 10767.82 | AR24: 10866.7 | AS24: 10400.95 | AT24: 10164.79 | AU24: 10302.55 | AV24: 10587.92 | AW24: 10499.36 | AX24: 11741.42 | AY24: 12745.29 | AZ24: 13748.33 | BA24: 15611.33 | BB24: 15793.6 | BC24: 14987.23 | BD24: 13488.86 | BE24: 14177.78 | BF24: 15511.23 | BG24: 14752.14 | BH24: 13763.34 | BI24: 11685.86 | BJ24: 11885.61 | BK24: 11466.12 | BL24: 11975.51 | BM24: 12135.2 | BN24: 11675.76 | BO24: 12227.17
... A31: =Ret!A31 -> A035720 | B31: 카카오 | C31: S102306 | D31: KRW bil | F31: 유동시가총액 | G31: 10980.88 | H31: 15780.19 | I31: 16189.25 | J31: 20802.75 | K31: 24716.97 | L31: 22156.01 | M31: 20134.8 | N31: 23267.11 | O31: 24694.37 | P31: 28030.04 | Q31: 31084.36 | R31: 31776.83 | S31: 36731.52 | T31: 39810.26 | U31: 52772.53 | V31: 47668.89 | W31: 50304.83 | X31: 38342.13 | Y31: 40829.72 | Z31: 39731.95 | AA31: 36660.23 | AB31: 27710.16 | AC31: 30684.83 | AD31: 34736.09 | AE31: 29343.56 | AF31: 27835 | AG31: 22940.48 | AH31: 24558.89 | AI31: 24113.4 | AJ31: 18767.87 | AK31: 16664.68 | AL31: 18548.87 | AM31: 17471.21 | AN31: 20202.72 | AO31: 20544.26 | AP31: 20122.33 | AQ31: 19150.21 | AR31: 18537.58 | AS31: 16203.68 | AT31: 16935.77 | AU31: 15884.63 | AV31: 14518.36 | AW31: 12488.59 | AX31: 16689.38 | AY31: 17957.85 | AZ31: 17366.49 | BA31: 17639.41 | BB31: 17780.34 | BC31: 16097.14 | BD31: 14343.27 | BE31: 13467.55 | BF31: 12990.3 | BG31: 12328.88 | BH31: 11981.85 | BI31: 12247.1 | BJ31: 13293.6 | BK31: 12664.04 | BL31: 12716.59 | BM31: 14308.66 | BN31: 12967.01 | BO31: 12691.14
A32: =Ret!A32 -> A329180 | B32: HD현대중공업 | C32: S102306 | D32: KRW bil | F32: 유동시가총액 | X32: 1675.39 | Y32: 1697.15 | Z32: 1544.84 | AA32: 1383.46 | AB32: 1443.04 | AC32: 1591.27 | AD32: 1757.81 | AE32: 2059.36 | AF32: 1930.04 | AG32: 2321.83 | AH32: 2029.58 | AI32: 2329.95 | AJ32: 2157.14 | AK32: 2044.6 | AL32: 2222.79 | AM32: 2175.9 | AN32: 2104.92 | AO32: 2021.33 | AP32: 1907.73 | AQ32: 2090.88 | AR32: 2214.88 | AS32: 2524.18 | AT32: 2677.51 | AU32: 2506.93 | AV32: 2322.93 | AW32: 1961.39 | AX32: 2405.15 | AY32: 2478.15 | AZ32: 2194.96 | BA32: 2268.06 | BB32: 2269.98 | BC32: 2648.95 | BD32: 2818.57 | BE32: 3409.88 | BF32: 4634.08 | BG32: 4256.33 | BH32: 4054.27 | BI32: 4010.35 | BJ32: 4831.74 | BK32: 6314.21 | BL32: 6830.33 | BM32: 6500.89 | BN32: 6127.53 | BO32: 8921.7
A33: =Ret!A33 -> A000810 | B33: 삼성화재 | C33: S102306 | D33: KRW bil | F33: 유동시가총액 | G33: 5916.73 | H33: 5668.26 | I33: 5466.37 | J33: 5326.61 | K33: 5808.02 | L33: 5652.73 | M33: 5559.55 | N33: 5839.08 | O33: 5824.44 | P33: 5218.7 | Q33: 5373.2 | R33: 5901.2 | S33: 6149.67 | T33: 6568.97 | U33: 6848.5 | V33: 6662.14 | W33: 7019.32 | X33: 7298.85 | Y33: 7174.62 | Z33: 6273.91 | AA33: 6273.91 | AB33: 6227.32 | AC33: 5916.73 | AD33: 6801.91 | AE33: 6522.38 | AF33: 6180.73 | AG33: 6242.85 | AH33: 6134.14 | AI33: 6056.49 | AJ33: 5714.85 | AK33: 6211.79 | AL33: 6382.61 | AM33: 6211.79 | AN33: 6304.97 | AO33: 6662.14 | AP33: 6398.14 | AQ33: 6988.26 | AR33: 7003.79 | AS33: 7143.56 | AT33: 7578.38 | AU33: 7656.03 | AV33: 8090.85 | AW33: 8028.74 | AX33: 8075.33 | AY33: 8169.75 | AZ33: 8200.81 | BA33: 9256.98 | BB33: 9505.49 | BC33: 9629.74 | BD33: 10825.69 | BE33: 12083.77 | BF33: 11571.22 | BG33: 10763.57 | BH33: 10701.44 | BI33: 10452.93 | BJ33: 12192.49 | BK33: 11136.33 | BL33: 11850.79 | BM33: 11881.86 | BN33: 11105.27 | BO33: 11633.35
A34: =Ret!A34 -> A259960 | B34: 크래프톤 | C34: S102306 | D34: KRW bil | F34: 유동시가총액 | W34: 12588.7 | X34: 12883.95 | Y34: 12053.39 | Z34: 12913.42 | AA34: 11814.28 | AB34: 7053.45 | AC34: 8575.73 | AD34: 8034.55 | AE34: 7349.21 | AF34: 7567.93 | AG34: 6388.96 | AH34: 6811.97 | AI34: 7191.23 | AJ34: 6132.58 | AK34: 5183.49 | AL34: 6598.95 | AM34: 4885.58 | AN34: 5243.98 | AO34: 4966.13 | AP34: 5484.27 | AQ34: 5649.55 | AR34: 5499.87 | AS34: 5668.65 | AT34: 4999.36 | AU34: 4510.48 | AV34: 4383.17 | AW34: 4768.93 | AX34: 6201.36 | AY34: 5636.54 | AZ34: 6246.3 | BA34: 6610.3 | BB34: 7174.79 | BC34: 6848.04 | BD34: 7083.19 | BE34: 7979.3 | BF34: 8336.64 | BG34: 9273.08 | BH34: 9711.6 | BI34: 9386.12 | BJ34: 8848.93 | BK34: 8642.66 | BL34: 10065.44 | BM34: 9500.34 | BN34: 9227.91 | BO34: 9979.58
A35: =Ret!A35 -> A015760 | B35: 한국전력 | C35: S102306 | D35: KRW bil | F35: 유동시가총액 | G35: 6805.67 | H35: 6170.56 | I35: 5559.38 | J35: 5450.24 | K35: 5856.32 | L35: 5827.75 | M35: 5695.35 | N35: 6124.95 | O35: 7827.47 | P35: 6512.98 | Q35: 6468.77 | R35: 6589.58 | S35: 6730.38 | T35: 7342.23 | U35: 7060.71 | V35: 7087.71 | W35: 7168.94 | X35: 7028.48 | Y35: 6744.95 | Z35: 6194.15 | AA35: 6597.14 | AB35: 6129.54 | AC35: 6904.66 | AD35: 6729.34 | AE35: 6863.03 | AF35: 6941.8 | AG35: 6692.39 | AH35: 6633.03 | AI35: 6217.54 | AJ35: 5958.83 | AK35: 4966.76 | AL35: 6136.7 | AM35: 6447.41 | AN35: 5866.46 | AO35: 5337.18 | AP35: 5314.95 | AQ35: 5512.67 | AR35: 5630.72 | AS35: 6070.03 | AT35: 5660.45 | AU35: 5250.87 | AV35: 5313.27 | AW35: 4990.02 | AX35: 5560.42 | AY35: 5576.38 | AZ35: 5817.84 | BA35: 7301.24 | BB35: 6474.08 | BC35: 6218.51 | BD35: 5716.18 | BE35: 5747.68 | BF35: 5792.94 | BG35: 6363.51 | BH35: 6024.95 | BI35: 6772.57 | BJ35: 7007.12 | BK35: 5878.36 | BL35: 6171.54 | BM35: 6258.13 | BN35: 6346.07 | BO35: 7518.55
A36: =Ret!A36 -> A066570 | B36: LG전자 | C36: S102306 | D36: KRW bil | F36: 유동시가총액 | G36: 5896.37 | H36: 6368.94 | I36: 6789.88 | J36: 7595.64 | K36: 9046.01 | L36: 9851.77 | M36: 9027.27 | N36: 9188.47 | O36: 14508.12 | P36: 16447.54 | Q36: 15748.79 | R36: 16132.4 | S36: 16939.02 | T36: 16347.5 | U36: 17586.99 | V36: 16941.6 | W36: 15274.33 | X36: 13714.63 | Y36: 12961.67 | Z36: 12425.73 | AA36: 14846.33 | AB36: 13714.63 | AC36: 13284.36 | AD36: 12963.64 | AE36: 12533.31 | AF36: 11296.12 | AG36: 9499.5 | AH36: 10155.75 | AI36: 10865.79 | AJ36: 8455.95 | AK36: 8778.7 | AL36: 10500.01 | AM36: 9305.85 | AN36: 10768.97 | AO36: 11963.13 | AP36: 12404.21 | AQ36: 11758.72 | AR36: 13211.08 | AS36: 13630.65 | AT36: 11661.9 | AU36: 10596.83 | AV36: 10855.03 | AW36: 10725.93 | AX36: 11048.68 | AY36: 10951.86 | AZ36: 10058.92 | BA36: 10217.3 | BB36: 10232.61 | BC36: 9994.37 | BD36: 11272.89 | BE36: 11929.04 | BF36: 11185.13 | BG36: 10690.4 | BH36: 11217.4 | BI36: 9616.88 | BJ36: 9548.83 | BK36: 8888.82 | BL36: 8963.33 | BM36: 8306.17 | BN36: 8122.15 | BO36: 7513.1
A37: =Ret!A37 -> A033780 | B37: KT&G | C37: S102306 | D37: KRW bil | F37: 유동시가총액 | G37: 8684.85 | H37: 8901.76 | I37: 8263.71 | J37: 8547.92 | K37: 8652.59 | L37: 8527.67 | M37: 8408.36 | N37: 8590.12 | O37: 8735.88 | P37: 8567.55 | Q37: 8451.65 | R37: 8782.91 | S37: 8890.81 | T37: 9095.82 | U37: 9085.75 | V37: 8860.81 | W37: 8785.45 | X37: 8743.49 | Y37: 8732.73 | Z37: 8664.82 | AA37: 8184.47 | AB37: 8147.04 | AC37: 8378.01 | AD37: 8456.99 | AE37: 8656.1 | AF37: 8908.77 | AG37: 8616.44 | AH37: 8584.99 | AI37: 8721.26 | AJ37: 9077.66 | AK37: 10031.54 | AL37: 10282.53 | AM37: 9252.11 | AN37: 9477.68 | AO37: 9088.33 | AP37: 8596.51 | AQ37: 8791.19 | AR37: 8565.77 | AS37: 8444.02 | AT37: 8423.62 | AU37: 8697.49 | AV37: 8501.19 | AW37: 8403.77 | AX37: 8689.47 | AY37: 8561.4 | AZ37: 8905.31 | BA37: 9149.93 | BB37: 9199.79 | BC37: 8796.38 | BD37: 8215.86 | BE37: 8678.31 | BF37: 9153.36 | BG37: 10452.99 | BH37: 10324.77 | BI37: 10366.3 | BJ37: 11345.23 | BK37: 9975.76 | BL37: 10301.76 | BM37: 9158.55 | BN37: 9419.52 | BO37: 10686.63
A38: =Ret!A38 -> A009540 | B38: HD한국조선해양 | C38: S102306 | D38: KRW bil | F38: 유동시가총액 | G38: 3753.49 | H38: 4121.12 | I38: 3969.9 | J38: 4051.66 | K38: 3915.39 | L38: 3756.41 | M38: 3562.21 | N38: 4679.94 | O38: 4935.99 | P38: 4276.34 | Q38: 5095.21 | R38: 6109.21 | S38: 7024.45 | T38: 6521.07 | U38: 6165.29 | V38: 6004.25 | W38: 5452.14 | X38: 4696.59 | Y38: 4742.63 | Z38: 4029.56 | AA38: 4359.2 | AB38: 3672.61 | AC38: 3895.75 | AD38: 3931.7 | AE38: 4059.96 | AF38: 4042.27 | AG38: 4154.16 | AH38: 3747.15 | AI38: 4300.15 | AJ38: 3227.7 | AK38: 3218.84 | AL38: 3466.78 | AM38: 3131.79 | AN38: 3526.03 | AO38: 3601.34 | AP38: 3454.4 | AQ38: 3779.78 | AR38: 4287.91 | AS38: 5200.99 | AT38: 5504.57 | AU38: 5522.42 | AV38: 4955.45 | AW38: 4032.6 | AX38: 4988.28 | AY38: 5399.13 | AZ38: 5070.27 | BA38: 4998.8 | BB38: 5289.16 | BC38: 5874.37 | BD38: 5825.23 | BE38: 7093.91 | BF38: 9251.5 | BG38: 8554.28 | BH38: 8388.92 | BI38: 8196.74 | BJ38: 9139.76 | BK38: 10190.05 | BL38: 10368.83 | BM38: 9564.35 | BN38: 8984.76 | BO38: 12158.48
A39: =Ret!A39 -> A034020 | B39: 두산에너빌리티 | C39: S102306 | D39: KRW bil | F39: 유동시가총액 | G39: 496.75 | H39: 534.03 | I39: 605.24 | J39: 1342.54 | K39: 2086.28 | L39: 1772.95 | M39: 2653.93 | N39: 3264.34 | O39: 2636.02 | P39: 2303.12 | Q39: 2079.3 | R39: 2551.06 | S39: 2739.94 | T39: 3908.59 | U39: 4700.56 | V39: 6219.93 | W39: 6027.21 | X39: 5985.05 | Y39: 7158.47 | Z39: 5588.15 | AA39: 7344.86 | AB39: 6467.88 | AC39: 7600.77 | AD39: 7396.55 | AE39: 7998.6 | AF39: 8059.98 | AG39: 7559.22 | AH39: 7411.95 | AI39: 8626.37 | AJ39: 6052.4 | AK39: 5627.67 | AL39: 7114.23 | AM39: 6575.25 | AN39: 7130.3 | AO39: 6942.44 | AP39: 7258.39 | AQ39: 7164.02 | AR39: 6902.18 | AS39: 7857.06 | AT39: 7588.07 | AU39: 7904.78 | AV39: 7128.19 | AW39: 5830.03 | AX39: 6863.97 | AY39: 6907.41 | AZ39: 6713.51 | BA39: 7061.36 | BB39: 7487.48 | BC39: 7351.13 | BD39: 9101.4 | BE39: 8795.1 | BF39: 8277.99 | BG39: 7957.07 | BH39: 7873.54 | BI39: 8814.32 | BJ39: 9297.9 | BK39: 7715.28 | BL39: 10506.85 | BM39: 11164.65 | BN39: 10307.52 | BO39: 12725.06
A40: =Ret!A40 -> A011200 | B40: HMM | C40: S102306 | D40: KRW bil | F40: 유동시가총액 | G40: 940.49 | H40: 1230.97 | I40: 1220.55 | J40: 1591.87 | K40: 1559.38 | L40: 1951.93 | M40: 2428.41 | N40: 3614.18 | O40: 3776.62 | P40: 3711.39 | Q40: 5168.38 | R40: 8257.69 | S40: 11348.71 | T40: 13867.43 | U40: 12730.63 | V40: 11599.09 | W40: 12179.04 | X40: 9773.6 | Y40: 7728.97 | Z40: 6844.01 | AA40: 10426.78 | AB40: 8488.72 | AC40: 11182.63 | AD40: 11298.91 | AE40: 11008.2 | AF40: 12578.03 | AG40: 9535.27 | AH40: 9632.18 | AI40: 8624.38 | AJ40: 7170.84 | AK40: 7403.4 | AL40: 8643.76 | AM40: 7577.83 | AN40: 8431.64 | AO40: 8741.77 | AP40: 7888.91 | AQ40: 7908.3 | AR40: 6880.99 | AS40: 7307.42 | AT40: 5072.96 | AU40: 4832.22 | AV40: 4716.2 | AW40: 4226.02 | AX40: 4493.43 | AY40: 5679.88 | AZ40: 5595.75 | BA40: 8909.06 | BB40: 7665.59 | BC40: 7728.99 | BD40: 8777.4 | BE40: 9769.36 | BF40: 9421.43 | BG40: 8784.71 | BH40: 9592.26 | BI40: 8862.36 | BJ40: 10483.05 | BK40: 10307.94 | BL40: 11113.43 | BM40: 11434.46 | BN40: 11416.95 | BO40: 10658.16
A41: =Ret!A41 -> A017670 | B41: SK텔레콤 | C41: S102306 | D41: KRW bil | F41: 유동시가총액 | G41: 9218.55 | H41: 9432.13 | I41: 9259.8 | J41: 9763.95 | K41: 11037.74 | L41: 10481.21 | M41: 9310.24 | N41: 10236.74 | O41: 10212.17 | P41: 10444.01 | Q41: 10623.79 | R41: 11806.44 | S41: 13030.01 | T41: 13616.75 | U41: 13729.47 | V41: 12905.61 | W41: 12766.25 | X41: 13873.08 | Y41: 13997.12 | Z41: 8015.74 | AA41: 8515.8 | AB41: 7764.47 | AC41: 7511.89 | AD41: 7856.96 | AE41: 7874.51 | AF41: 7798.36 | AG41: 7095.01 | AH41: 7318.01 | AI41: 7107.51 | AJ41: 6983.53 | AK41: 6922.38 | AL41: 6910.75 | AM41: 6559.69 | AN41: 6455.1 | AO41: 6298.7 | AP41: 6714.89 | AQ41: 6620 | AR41: 6900.83 | AS41: 6476.51 | AT41: 6413.07 | AU41: 6631.77 | AV41: 7128.01 | AW41: 6700.77 | AX41: 7053.76 | AY41: 6660.35 | AZ41: 6708.8 | BA41: 7042.95 | BB41: 7016.22 | BC41: 6867.97 | BD41: 6822.33 | BE41: 6872.63 | BF41: 7189.38 | BG41: 7313.03 | BH41: 7405.77 | BI41: 7510.54 | BJ41: 8137.06 | BK41: 7314.22 | BL41: 7339.53 | BM41: 7406.99 | BN41: 7296.75 | BO41: 7109.83
A42: =Ret!A42 -> A003550 | B42: LG | C42: S102306 | D42: KRW bil | F42: 유동시가총액 | G42: 5749.4 | H42: 5851.4 | I42: 6602.53 | J42: 6862.18 | K42: 7687.5 | L42: 6888.08 | M42: 6302.45 | N42: 6562.73 | O42: 8135.21 | P42: 9244.48 | Q42: 8759.4 | R42: 8440.71 | S42: 11811.39 | T42: 8591.91 | U42: 8719.51 | V42: 8013.44 | W42: 8107.02 | X42: 7911.36 | Y42: 7758.24 | Z42: 6670.59 | AA42: 7415.24 | AB42: 6782.79 | AC42: 6892.78 | AD42: 7002.77 | AE42: 6718.63 | AF42: 7348.55 | AG42: 7072.86 | AH42: 7323.86 | AI42: 7385.78 | AJ42: 6637.28 | AK42: 7089.98 | AL42: 7528.63 | AM42: 6991.51 | AN42: 7396.63 | AO42: 7333.84 | AP42: 7367.97 | AQ42: 7766.31 | AR42: 7641.9 | AS42: 7783.63 | AT42: 7360.65 | AU42: 7221.74 | AV42: 7340.96 | AW42: 6745.79 | AX42: 7348.72 | AY42: 7506 | AZ42: 7165.22 | BA42: 8183.15 | BB42: 7594.89 | BC42: 6856.84 | BD42: 6987.68 | BE42: 6898.35 | BF42: 7420.43 | BG42: 6778.53 | BH42: 6769.97 | BI42: 6478.97 | BJ42: 6410.5 | BK42: 6162.3 | BL42: 6410.5 | BM42: 5691.57 | BN42: 5528.95 | BO42: 5700.13
